2025-04-09 03:51:20,709 - __main__ - INFO - Starting Facial Recognition Surveillance System
2025-04-09 03:51:20,710 - __main__ - INFO - Initializing surveillance system...
2025-04-09 03:51:20,710 - __main__ - INFO - Initializing face detector...
2025-04-09 03:51:21,650 - __main__ - INFO - Initializing face recognizer...
2025-04-09 03:51:21,650 - __main__ - INFO - Initializing face database...
2025-04-09 03:51:21,652 - database.face_database - INFO - Loaded database with 54 identities
2025-04-09 03:51:21,652 - __main__ - INFO - Initializing memory systems...
2025-04-09 03:51:21,652 - __main__ - INFO - Initializing embedding cache...
2025-04-09 03:51:21,652 - __main__ - INFO - Initializing face tracker...
2025-04-09 03:51:21,653 - __main__ - INFO - Initializing dynamic resolution scaler...
2025-04-09 03:51:21,653 - __main__ - INFO - Initializing ROI manager...
2025-04-09 03:51:21,653 - __main__ - ERROR - Error in main execution: 0
Traceback (most recent call last):
  File "F:\projects\facial_surveillance_system\main.py", line 252, in main
    engine, database = build_engine()
  File "F:\projects\facial_surveillance_system\main.py", line 111, in build_engine
    roi_manager = ROIManager(DETECTION_CONFIG.get('roi_config', {}))
  File "F:\projects\facial_surveillance_system\optimization\roi_manager.py", line 48, in __init__
    self.cell_width = frame_size[0] // grid_size[0]
KeyError: 0
2025-04-09 03:51:21,690 - __main__ - INFO - Facial Recognition Surveillance System shut down
